<!-- 
    需求: 创建机器人模型，底盘为长方体，
         在长方体的前面添加一摄像头，
         摄像头可以沿着 Z 轴 360 度旋转
 -->
<robot name="mycar">
    <!-- 添加一个尺寸极小的 link ，再去关联初始 link 与 base_link,
         关节的高度刚好和base_link下沉的高度一致(半个底盘高度) -->
    <link name="base_footprint">
        <visual>
            <geometry>
                <sphere radius="0.001" />
            </geometry>
        </visual>
    </link>
    <!-- 底盘 -->
    <link name="base_link">
        <visual>
            <geometry>
                <box size="0.5 0.2 0.1" />
            </geometry>
            <origin xyz="0 0 0" rpy="0 0 0" />
            <material name="car_color">
                <color rgba="0 0 1.0 0.5" />
            </material>
        </visual>
    </link>

    <!-- 摄像头 -->
    <link name="camera">
        <visual>
            <geometry>
                <box size="0.02 0.05 0.05" />
            </geometry>
            <origin xyz="0 0 0" rpy="0 0 0" />
            <material name="camera_color">
                <color rgba="1 0 0 0.5" />
            </material>
        </visual>
    </link>

    <!-- 关联 base_footprint 与 base_link -->
    <joint name="base_link2base_footprint" type="fixed">
        <parent link="base_footprint" />
        <child link="base_link" />
        <origin xyz="0 0 0.05" />
    </joint>

    <!-- 关节 -->
    <joint name="camera2baselink" type="continuous">
        <!-- 父级 link -->
        <parent link="base_link"/>
        <!-- 子级 link -->
        <child link="camera" />
        <!-- 需要计算两个 link 的物理中心之间的偏移量 -->
        <origin xyz="0.2 0 0.075" rpy="0 0 0" />
        <!-- 设置关节旋转参数的坐标轴 -->
        <axis xyz="0 0 1" />
    </joint>

</robot>
